wandb: Currently logged in as: thomas-rothe (rothe). Use `wandb login --relogin` to force relogin
wandb: Currently logged in as: thomas-rothe (rothe). Use `wandb login --relogin` to force relogin
wandb: Currently logged in as: thomas-rothe (rothe). Use `wandb login --relogin` to force relogin
wandb: Currently logged in as: thomas-rothe (rothe). Use `wandb login --relogin` to force relogin
wandb: wandb version 0.13.11 is available!  To upgrade, please run:
wandb:  $ pip install wandb --upgrade
wandb: Tracking run with wandb version 0.13.10
wandb: Run data is saved locally in /data1/s1930443/wandb/wandb/run-20230312_175729-e22qa7h0
wandb: Run `wandb offline` to turn off syncing.
wandb: wandb version 0.13.11 is available!  To upgrade, please run:
wandb:  $ pip install wandb --upgrade
wandb: Tracking run with wandb version 0.13.10
wandb: wandb version 0.13.11 is available!  To upgrade, please run:
wandb:  $ pip install wandb --upgrade
wandb: Tracking run with wandb version 0.13.10
wandb: Run data is saved locally in /data1/s1930443/wandb/wandb/run-20230312_175729-i0b4v5gi
wandb: Run `wandb offline` to turn off syncing.
wandb: Run data is saved locally in /data1/s1930443/wandb/wandb/run-20230312_175729-3x5qxjlr
wandb: Run `wandb offline` to turn off syncing.
wandb: Syncing run pretty-jazz-11
wandb: ‚≠êÔ∏è View project at https://wandb.ai/rothe/t5-deepspeed-alice-initial-test
wandb: üöÄ View run at https://wandb.ai/rothe/t5-deepspeed-alice-initial-test/runs/e22qa7h0
wandb: Syncing run giddy-morning-12
wandb: ‚≠êÔ∏è View project at https://wandb.ai/rothe/t5-deepspeed-alice-initial-test
wandb: üöÄ View run at https://wandb.ai/rothe/t5-deepspeed-alice-initial-test/runs/i0b4v5gi
wandb: Syncing run breezy-night-9
wandb: ‚≠êÔ∏è View project at https://wandb.ai/rothe/t5-deepspeed-alice-initial-test
wandb: üöÄ View run at https://wandb.ai/rothe/t5-deepspeed-alice-initial-test/runs/3x5qxjlr
wandb: wandb version 0.13.11 is available!  To upgrade, please run:
wandb:  $ pip install wandb --upgrade
wandb: Tracking run with wandb version 0.13.10
wandb: Run data is saved locally in /data1/s1930443/wandb/wandb/run-20230312_175729-g0mb5cj0
wandb: Run `wandb offline` to turn off syncing.
wandb: Syncing run youthful-plasma-10
wandb: ‚≠êÔ∏è View project at https://wandb.ai/rothe/t5-deepspeed-alice-initial-test
wandb: üöÄ View run at https://wandb.ai/rothe/t5-deepspeed-alice-initial-test/runs/g0mb5cj0
Traceback (most recent call last):
  File "/data1/s1930443/conda_pkgs/T5-test-env/lib/python3.10/site-packages/wandb/sdk/wandb_config.py", line 166, in __getattr__
    return self.__getitem__(key)
  File "/data1/s1930443/conda_pkgs/T5-test-env/lib/python3.10/site-packages/wandb/sdk/wandb_config.py", line 133, in __getitem__
    return self._items[key]
KeyError: 'VALID_BATCH_SIZE'

The above exception was the direct cause of the following exception:

Traceback (most recent call last):
  File "/home/s1930443/MRP1/t5_deepspeed_initial.py", line 167, in <module>
    main(**script_kwargs)
  File "/home/s1930443/MRP1/t5_deepspeed_initial.py", line 99, in main
    per_device_eval_batch_size=config.VALID_BATCH_SIZE,
  File "/data1/s1930443/conda_pkgs/T5-test-env/lib/python3.10/site-packages/wandb/sdk/wandb_config.py", line 168, in __getattr__
    raise AttributeError(
AttributeError: <class 'wandb.sdk.wandb_config.Config'> object has no attribute 'VALID_BATCH_SIZE'
wandb: Waiting for W&B process to finish... (failed 1). Press Control-C to abort syncing.
Traceback (most recent call last):
  File "/data1/s1930443/conda_pkgs/T5-test-env/lib/python3.10/site-packages/wandb/sdk/wandb_config.py", line 166, in __getattr__
    return self.__getitem__(key)
  File "/data1/s1930443/conda_pkgs/T5-test-env/lib/python3.10/site-packages/wandb/sdk/wandb_config.py", line 133, in __getitem__
    return self._items[key]
KeyError: 'VALID_BATCH_SIZE'

The above exception was the direct cause of the following exception:

Traceback (most recent call last):
  File "/home/s1930443/MRP1/t5_deepspeed_initial.py", line 167, in <module>
    main(**script_kwargs)
  File "/home/s1930443/MRP1/t5_deepspeed_initial.py", line 99, in main
    per_device_eval_batch_size=config.VALID_BATCH_SIZE,
  File "/data1/s1930443/conda_pkgs/T5-test-env/lib/python3.10/site-packages/wandb/sdk/wandb_config.py", line 168, in __getattr__
    raise AttributeError(
AttributeError: <class 'wandb.sdk.wandb_config.Config'> object has no attribute 'VALID_BATCH_SIZE'
wandb: Waiting for W&B process to finish... (failed 1). Press Control-C to abort syncing.
Traceback (most recent call last):
  File "/data1/s1930443/conda_pkgs/T5-test-env/lib/python3.10/site-packages/wandb/sdk/wandb_config.py", line 166, in __getattr__
    return self.__getitem__(key)
  File "/data1/s1930443/conda_pkgs/T5-test-env/lib/python3.10/site-packages/wandb/sdk/wandb_config.py", line 133, in __getitem__
    return self._items[key]
KeyError: 'VALID_BATCH_SIZE'

The above exception was the direct cause of the following exception:

Traceback (most recent call last):
  File "/home/s1930443/MRP1/t5_deepspeed_initial.py", line 167, in <module>
    main(**script_kwargs)
  File "/home/s1930443/MRP1/t5_deepspeed_initial.py", line 99, in main
    per_device_eval_batch_size=config.VALID_BATCH_SIZE,
  File "/data1/s1930443/conda_pkgs/T5-test-env/lib/python3.10/site-packages/wandb/sdk/wandb_config.py", line 168, in __getattr__
    raise AttributeError(
AttributeError: <class 'wandb.sdk.wandb_config.Config'> object has no attribute 'VALID_BATCH_SIZE'
wandb: Waiting for W&B process to finish... (failed 1). Press Control-C to abort syncing.
Traceback (most recent call last):
  File "/data1/s1930443/conda_pkgs/T5-test-env/lib/python3.10/site-packages/wandb/sdk/wandb_config.py", line 166, in __getattr__
    return self.__getitem__(key)
  File "/data1/s1930443/conda_pkgs/T5-test-env/lib/python3.10/site-packages/wandb/sdk/wandb_config.py", line 133, in __getitem__
    return self._items[key]
KeyError: 'VALID_BATCH_SIZE'

The above exception was the direct cause of the following exception:

Traceback (most recent call last):
  File "/home/s1930443/MRP1/t5_deepspeed_initial.py", line 167, in <module>
    main(**script_kwargs)
  File "/home/s1930443/MRP1/t5_deepspeed_initial.py", line 99, in main
    per_device_eval_batch_size=config.VALID_BATCH_SIZE,
  File "/data1/s1930443/conda_pkgs/T5-test-env/lib/python3.10/site-packages/wandb/sdk/wandb_config.py", line 168, in __getattr__
    raise AttributeError(
AttributeError: <class 'wandb.sdk.wandb_config.Config'> object has no attribute 'VALID_BATCH_SIZE'
wandb: Waiting for W&B process to finish... (failed 1). Press Control-C to abort syncing.
wandb: üöÄ View run pretty-jazz-11 at: https://wandb.ai/rothe/t5-deepspeed-alice-initial-test/runs/e22qa7h0
wandb: Synced 5 W&B file(s), 0 media file(s), 0 artifact file(s) and 0 other file(s)
wandb: Find logs at: /data1/s1930443/wandb/wandb/run-20230312_175729-e22qa7h0/logs
wandb: üöÄ View run giddy-morning-12 at: https://wandb.ai/rothe/t5-deepspeed-alice-initial-test/runs/i0b4v5gi
wandb: Synced 5 W&B file(s), 0 media file(s), 0 artifact file(s) and 0 other file(s)
wandb: Find logs at: /data1/s1930443/wandb/wandb/run-20230312_175729-i0b4v5gi/logs
wandb: üöÄ View run breezy-night-9 at: https://wandb.ai/rothe/t5-deepspeed-alice-initial-test/runs/3x5qxjlr
wandb: Synced 5 W&B file(s), 0 media file(s), 0 artifact file(s) and 0 other file(s)
wandb: Find logs at: /data1/s1930443/wandb/wandb/run-20230312_175729-3x5qxjlr/logs
wandb: üöÄ View run youthful-plasma-10 at: https://wandb.ai/rothe/t5-deepspeed-alice-initial-test/runs/g0mb5cj0
wandb: Synced 5 W&B file(s), 0 media file(s), 0 artifact file(s) and 0 other file(s)
wandb: Find logs at: /data1/s1930443/wandb/wandb/run-20230312_175729-g0mb5cj0/logs
